// `await`式で評価した右辺のPromiseがRejectedとなったため、例外がthrowされる